Workbook

Sheet RAW DATA
A1: CUSTOMER ID | B1: GENDER | C1: AGE | D1: CITY | E1: SIGNUP DATE | F1: ORDER ID | G1: ORDER DATE | H1: RESTAURANT NAME | I1: DISH NAME | J1: CATEGORY | K1: QUANTITY | L1: PRICE | M1: PAYMENT METHOD | N1: ORDER FREQUENCY | O1: LAST ORDER DATE | P1: LOYALTY POINTS | Q1: CHURNED | R1: RATING | S1: RATING DATE | T1: DELIVERY STATUS | U1: REVENUE
A2: C3497 | B2: Other | C2: Senior | D2: Lahore | E2: 45461 | F2: O7497 | G2: 45404 | H2: McDonald's | I2: Sandwich | J2: Chinese | K2: 4 | L2: 222.31 | M2: Wallet | N2: 4 | O2: 45788 | P2: 450 | Q2: Inactive | R2: 4 | S2: 45816 | T2: Delivered | U2: =Table1[[#This Row],[QUANTITY]]*Table1[[#This Row],[PRICE]] -> 889.24
A3: C4774 | B3: Other | C3: Adult | D3: Islamabad | E3: 45259 | F3: O8774 | G3: 45405 | H3: Burger King | I3: Fries | J3: Italian | K3: 3 | L3: 509.02 | M3: Cash | N3: 46 | O3: 45621 | P3: 193 | Q3: Active | S3: 45751 | T3: Cancelled | U3: =Table1[[#This Row],[QUANTITY]]*Table1[[#This Row],[PRICE]] -> 1527.06
A4: C1965 | B4: Female | C4: Teenager | D4: Lahore | E4: 45641 | F4: O5965 | G4: 45405 | H4: Pizza Hut | I4: Fries | J4: Italian | K4: 2 | L4: 321.96 | M4: Wallet | N4: 25 | O4: 45847 | P4: 222 | Q4: Inactive | S4: 45815 | T4: Cancelled | U4: =Table1[[#This Row],[QUANTITY]]*Table1[[#This Row],[PRICE]] -> 643.92
A5: C4045 | B5: Other | C5: Teenager | D5: Multan | E5: 45692 | F5: O8045 | G5: 45405 | H5: Pizza Hut | I5: Fries | J5: Fast Food | K5: 4 | L5: 889.71 | M5: Cash | N5: 13 | O5: 45694 | P5: 126 | Q5: Active | R5: 4 | S5: 45637 | T5: Delayed | U5: =Table1[[#This Row],[QUANTITY]]*Table1[[#This Row],[PRICE]] -> 3558.84
A6: C6269 | B6: Female | C6: Adult | D6: Islamabad | E6: 45595 | F6: O10269 | G6: 45405 | H6: Pizza Hut | I6: Pasta | J6: Fast Food | K6: 4 | L6: 163.58 | M6: Card | N6: 6 | O6: 45858 | P6: 272 | Q6: Active | S6: 45721 | T6: Cancelled | U6: =Table1[[#This Row],[QUANTITY]]*Table1[[#This Row],[PRICE]] -> 654.32
A7: C1210 | B7: Other | C7: Adult | D7: Multan | E7: 45482 | F7: O5210 | G7: 45405 | H7: McDonald's | I7: Sandwich | J7: Dessert | K7: 3 | L7: 1259.72 | M7: Card | N7: 39 | O7: 45759 | P7: 59 | Q7: Inactive | R7: 1 | S7: 45842 | T7: Delayed | U7: =Table1[[#This Row],[QUANTITY]]*Table1[[#This Row],[PRICE]] -> 3779.16
A8: C4850 | B8: Other | C8: Teenager | D8: Islamabad | E8: 45852 | F8: O8850 | G8: 45405 | H8: Subway | I8: Sandwich | J8: Italian | K8: 1 | L8: 452.54 | M8: Cash | N8: 27 | O8: 45838 | P8: 467 | Q8: Inactive | R8: 5 | S8: 45598 | T8: Delayed | U8: =Table1[[#This Row],[QUANTITY]]*Table1[[#This Row],[PRICE]] -> 452.54
A9: C2443 | B9: Male | C9: Adult | D9: Islamabad | E9: 45169 | F9: O6443 | G9: 45405 | H9: Pizza Hut | I9: Sandwich | J9: Continental | K9: 3 | L9: 1399.51 | M9: Card | N9: 6 | O9: 45712 | P9: 4 | Q9: Inactive | S9: 45535 | T9: Cancelled | U9: =Table1[[#This Row],[QUANTITY]]*Table1[[#This Row],[PRICE]] -> 4198.53
A10: C4874 | B10: Female | C10: Teenager | D10: Lahore | E10: 45392 | F10: O8874 | G10: 45405 | H10: Pizza Hut | I10: Burger | J10: Continental | K10: 1 | L10: 501.59 | M10: Card | N10: 4 | O10: 45698 | P10: 139 | Q10: Inactive | R10: 2 | S10: 45549 | T10: Delayed | U10: =Table1[[#This Row],[QUANTITY]]*Table1[[#This Row],[PRICE]] -> 501.59
A11: C2206 | B11: Other | C11: Senior | D11: Peshawar | E11: 45372 | F11: O6206 | G11: 45405 | H11: Burger King | I11: Pizza | J11: Continental | K11: 5 | L11: 783.53 | M11: Card | N11: 11 | O11: 45718 | P11: 276 | Q11: Active | R11: 2 | S11: 45789 | T11: Delivered | U11: =Table1[[#This Row],[QUANTITY]]*Table1[[#This Row],[PRICE]] -> 3917.65
A12: C5783 | B12: Female | C12: Teenager | D12: Multan | E12: 45837 | F12: O9783 | G12: 45405 | H12: Pizza Hut | I12: Pasta | J12: Continental | K12: 4 | L12: 364.24 | M12: Card | N12: 25 | O12: 45695 | P12: 220 | Q12: Inactive | R12: 2 | S12: 45880 | T12: Delayed | U12: =Table1[[#This Row],[QUANTITY]]*Table1[[#This Row],[PRICE]] -> 1456.96
A13: C4712 | B13: Male | C13: Adult | D13: Peshawar | E13: 45236 | F13: O8712 | G13: 45405 | H13: Burger King | I13: Pasta | J13: Chinese | K13: 4 | L13: 1251.7 | M13: Card | N13: 22 | O13: 45857 | P13: 218 | Q13: Inactive | R13: 2 | S13: 45825 | T13: Delayed | U13: =Table1[[#This Row],[QUANTITY]]*Table1[[#This Row],[PRICE]] -> 5006.8
A14: C3132 | B14: Male | C14: Adult | D14: Islamabad | E14: 45702 | F14: O7132 | G14: 45406 | H14: KFC | I14: Burger | J14: Fast Food | K14: 4 | L14: 417.39 | M14: Wallet | N14: 37 | O14: 45573 | P14: 180 | Q14: Active | R14: 3 | S14: 45633 | T14: Delivered | U14: =Table1[[#This Row],[QUANTITY]]*Table1[[#This Row],[PRICE]] -> 1669.56
A15: C3540 | B15: Male | C15: Senior | D15: Islamabad | E15: 45254 | F15: O7540 | G15: 45406 | H15: KFC | I15: Pasta | J15: Fast Food | K15: 1 | L15: 153.81 | M15: Card | N15: 17 | O15: 45706 | P15: 106 | Q15: Active | R15: 3 | S15: 45653 | T15: Delayed | U15: =Table1[[#This Row],[QUANTITY]]*Table1[[#This Row],[PRICE]] -> 153.81
A16: C4265 | B16: Other | C16: Adult | D16: Multan | E16: 45368 | F16: O8265 | G16: 45406 | H16: Burger King | I16: Fries | J16: Fast Food | K16: 3 | L16: 606.24 | M16: Cash | N16: 10 | O16: 45610 | P16: 125 | Q16: Inactive | R16: 2 | S16: 45771 | T16: Delayed | U16: =Table1[[#This Row],[QUANTITY]]*Table1[[#This Row],[PRICE]] -> 1818.72
A17: C6582 | B17: Female | C17: Teenager | D17: Islamabad | E17: 45211 | F17: O10582 | G17: 45406 | H17: Burger King | I17: Burger | J17: Dessert | K17: 4 | L17: 1220.38 | M17: Cash | N17: 42 | O17: 45833 | P17: 409 | Q17: Active | S17: 45546 | T17: Cancelled | U17: =Table1[[#This Row],[QUANTITY]]*Table1[[#This Row],[PRICE]] -> 4881.52
A18: C3195 | B18: Other | C18: Adult | D18: Karachi | E18: 45838 | F18: O7195 | G18: 45406 | H18: Burger King | I18: Pizza | J18: Fast Food | K18: 5 | L18: 1300.96 | M18: Card | N18: 8 | O18: 45698 | P18: 269 | Q18: Inactive | S18: 45590 | T18: Cancelled | U18: =Table1[[#This Row],[QUANTITY]]*Table1[[#This Row],[PRICE]] -> 6504.8
A19: C3466 | B19: Male | C19: Senior | D19: Karachi | E19: 45241 | F19: O7466 | G19: 45406 | H19: McDonald's | I19: Pasta | J19: Italian | K19: 4 | L19: 476.38 | M19: Wallet | N19: 27 | O19: 45624 | P19: 222 | Q19: Inactive | S19: 45785 | T19: Cancelled | U19: =Table1[[#This Row],[QUANTITY]]*Table1[[#This Row],[PRICE]] -> 1905.52
A20: C2671 | B20: Female | C20: Senior | D20: Multan | E20: 45603 | F20: O6671 | G20: 45406 | H20: McDonald's | I20: Sandwich | J20: Chinese | K20: 3 | L20: 644.27 | M20: Cash | N20: 17 | O20: 45638 | P20: 265 | Q20: Inactive | R20: 2 | S20: 45821 | T20: Delivered | U20: =Table1[[#This Row],[QUANTITY]]*Table1[[#This Row],[PRICE]] -> 1932.81
A21: C4172 | B21: Female | C21: Teenager | D21: Karachi | E21: 45515 | F21: O8172 | G21: 45406 | H21: McDonald's | I21: Sandwich | J21: Continental | K21: 1 | L21: 125.81 | M21: Card | N21: 47 | O21: 45755 | P21: 311 | Q21: Active | S21: 45635 | T21: Cancelled | U21: =Table1[[#This Row],[QUANTITY]]*Table1[[#This Row],[PRICE]] -> 125.81
A22: C1254 | B22: Other | C22: Adult | D22: Islamabad | E22: 45286 | F22: O5254 | G22: 45406 | H22: Pizza Hut | I22: Sandwich | J22: Continental | K22: 1 | L22: 1492.01 | M22: Cash | N22: 28 | O22: 45725 | P22: 433 | Q22: Active | S22: 45559 | T22: Cancelled | U22: =Table1[[#This Row],[QUANTITY]]*Table1[[#This Row],[PRICE]] -> 1492.01
A23: C5660 | B23: Male | C23: Adult | D23: Karachi | E23: 45784 | F23: O9660 | G23: 45406 | H23: Burger King | I23: Pasta | J23: Italian | K23: 4 | L23: 1498.16 | M23: Cash | N23: 42 | O23: 45638 | P23: 446 | Q23: Active | R23: 4 | S23: 45606 | T23: Delivered | U23: =Table1[[#This Row],[QUANTITY]]*Table1[[#This Row],[PRICE]] -> 5992.64
A24: C1071 | B24: Male | C24: Senior | D24: Peshawar | E24: 45384 | F24: O5071 | G24: 45406 | H24: Pizza Hut | I24: Pizza | J24: Italian | K24: 4 | L24: 793.19 | M24: Wallet | N24: 32 | O24: 45693 | P24: 133 | Q24: Active | R24: 1 | S24: 45528 | T24: Delivered | U24: =Table1[[#This Row],[QUANTITY]]*Table1[[#This Row],[PRICE]] -> 3172.76
A25: C2643 | B25: Male | C25: Senior | D25: Islamabad | E25: 45596 | F25: O6643 | G25: 45406 | H25: Pizza Hut | I25: Sandwich | J25: Continental | K25: 5 | L25: 322.77 | M25: Card | N25: 48 | O25: 45660 | P25: 405 | Q25: Inactive | R25: 1 | S25: 45653 | T25: Delayed | U25: =Table1[[#This Row],[QUANTITY]]*Table1[[#This Row],[PRICE]] -> 1613.85
A26: C5290 | B26: Other | C26: Senior | D26: Karachi | E26: 45497 | F26: O9290 | G26: 45407 | H26: McDonald's | I26: Fries | J26: Chinese | K26: 2 | L26: 1255.34 | M26: Card | N26: 42 | O26: 45620 | P26: 102 | Q26: Inactive | S26: 45784 | T26: Cancelled | U26: =Table1[[#This Row],[QUANTITY]]*Table1[[#This Row],[PRICE]] -> 2510.68
A27: C2622 | B27: Male | C27: Teenager | D27: Karachi | E27: 45246 | F27: O6622 | G27: 45407 | H27: Burger King | I27: Fries | J27: Chinese | K27: 2 | L27: 1048.17 | M27: Wallet | N27: 9 | O27: 45752 | P27: 407 | Q27: Active | R27: 3 | S27: 45624 | T27: Delivered | U27: =Table1[[#This Row],[QUANTITY]]*Table1[[#This Row],[PRICE]] -> 2096.34
A28: C2365 | B28: Other | C28: Teenager | D28: Multan | E28: 45475 | F28: O6365 | G28: 45407 | H28: Subway | I28: Pasta | J28: Chinese | K28: 5 | L28: 1315.23 | M28: Card | N28: 21 | O28: 45742 | P28: 155 | Q28: Active | R28: 1 | S28: 45650 | T28: Delivered | U28: =Table1[[#This Row],[QUANTITY]]*Table1[[#This Row],[PRICE]] -> 6576.15
A29: C3943 | B29: Female | C29: Teenager | D29: Multan | E29: 45837 | F29: O7943 | G29: 45407 | H29: McDonald's | I29: Pizza | J29: Italian | K29: 1 | L29: 624.55 | M29: Wallet | N29: 13 | O29: 45676 | P29: 214 | Q29: Active | S29: 45591 | T29: Cancelled | U29: =Table1[[#This Row],[QUANTITY]]*Table1[[#This Row],[PRICE]] -> 624.55
A30: C6955 | B30: Other | C30: Teenager | D30: Karachi | E30: 45808 | F30: O10955 | G30: 45407 | H30: Subway | I30: Pizza | J30: Chinese | K30: 2 | L30: 751.25 | M30: Card | N30: 1 | O30: 45860 | P30: 77 | Q30: Inactive | R30: 5 | S30: 45624 | T30: Delivered | U30: =Table1[[#This Row],[QUANTITY]]*Table1[[#This Row],[PRICE]] -> 1502.5
A31: C1850 | B31: Male | C31: Teenager | D31: Karachi | E31: 45198 | F31: O5850 | G31: 45407 | H31: Pizza Hut | I31: Fries | J31: Continental | K31: 3 | L31: 726.99 | M31: Wallet | N31: 28 | O31: 45544 | P31: 192 | Q31: Inactive | R31: 3 | S31: 45605 | T31: Delivered | U31: =Table1[[#This Row],[QUANTITY]]*Table1[[#This Row],[PRICE]] -> 2180.97
A32: C5984 | B32: Male | C32: Senior | D32: Islamabad | E32: 45601 | F32: O9984 | G32: 45407 | H32: Burger King | I32: Fries | J32: Italian | K32: 1 | L32: 654.82 | M32: Cash | N32: 47 | O32: 45829 | P32: 177 | Q32: Active | R32: 1 | S32: 45568 | T32: Delayed | U32: =Table1[[#This Row],[QUANTITY]]*Table1[[#This Row],[PRICE]] -> 654.82
A33: C6458 | B33: Male | C33: Adult | D33: Peshawar | E33: 45487 | F33: O10458 | G33: 45407 | H33: Pizza Hut | I33: Pasta | J33: Dessert | K33: 3 | L33: 341.78 | M33: Cash | N33: 19 | O33: 45605 | P33: 3 | Q33: Inactive | R33: 2 | S33: 45793 | T33: Delayed | U33: =Table1[[#This Row],[QUANTITY]]*Table1[[#This Row],[PRICE]] -> 1025.34
A34: C2096 | B34: Female | C34: Teenager | D34: Peshawar | E34: 45573 | F34: O6096 | G34: 45407 | H34: Pizza Hut | I34: Sandwich | J34: Italian | K34: 2 | L34: 1226.31 | M34: Card | N34: 13 | O34: 45605 | P34: 272 | Q34: Inactive | R34: 4 | S34: 45851 | T34: Delayed | U34: =Table1[[#This Row],[QUANTITY]]*Table1[[#This Row],[PRICE]] -> 2452.62
A35: C3169 | B35: Female | C35: Adult | D35: Peshawar | E35: 45367 | F35: O7169 | G35: 45407 | H35: Pizza Hut | I35: Burger | J35: Chinese | K35: 5 | L35: 466.95 | M35: Card | N35: 15 | O35: 45818 | P35: 436 | Q35: Inactive | R35: 3 | S35: 45822 | T35: Delayed | U35: =Table1[[#This Row],[QUANTITY]]*Table1[[#This Row],[PRICE]] -> 2334.75
A36: C5924 | B36: Female | C36: Adult | D36: Karachi | E36: 45383 | F36: O9924 | G36: 45408 | H36: McDonald's | I36: Fries | J36: Fast Food | K36: 1 | L36: 1098.54 | M36: Wallet | N36: 13 | O36: 45813 | P36: 15 | Q36: Active | R36: 4 | S36: 45643 | T36: Delayed | U36: =Table1[[#This Row],[QUANTITY]]*Table1[[#This Row],[PRICE]] -> 1098.54
A37: C5556 | B37: Female | C37: Adult | D37: Lahore | E37: 45390 | F37: O9556 | G37: 45408 | H37: KFC | I37: Pizza | J37: Italian | K37: 4 | L37: 285.59 | M37: Cash | N37: 45 | O37: 45650 | P37: 263 | Q37: Inactive | R37: 4 | S37: 45537 | T37: Delayed | U37: =Table1[[#This Row],[QUANTITY]]*Table1[[#This Row],[PRICE]] -> 1142.36
A38: C3430 | B38: Other | C38: Teenager | D38: Lahore | E38: 45429 | F38: O7430 | G38: 45408 | H38: Burger King | I38: Sandwich | J38: Chinese | K38: 2 | L38: 1283.58 | M38: Wallet | N38: 49 | O38: 45678 | P38: 375 | Q38: Inactive | R38: 1 | S38: 45644 | T38: Delivered | U38: =Table1[[#This Row],[QUANTITY]]*Table1[[#This Row],[PRICE]] -> 2567.16
A39: C3013 | B39: Female | C39: Teenager | D39: Multan | E39: 45328 | F39: O7013 | G39: 45408 | H39: Subway | I39: Fries | J39: Continental | K39: 1 | L39: 240.55 | M39: Wallet | N39: 47 | O39: 45853 | P39: 412 | Q39: Inactive | S39: 45815 | T39: Cancelled | U39: =Table1[[#This Row],[QUANTITY]]*Table1[[#This Row],[PRICE]] -> 240.55
A40: C1478 | B40: Other | C40: Adult | D40: Karachi | E40: 45527 | F40: O5478 | G40: 45408 | H40: Subway | I40: Sandwich | J40: Fast Food | K40: 5 | L40: 481.17 | M40: Card | N40: 48 | O40: 45718 | P40: 391 | Q40: Inactive | S40: 45578 | T40: Cancelled | U40: =Table1[[#This Row],[QUANTITY]]*Table1[[#This Row],[PRICE]] -> 2405.85
...

Sheet PROJECT TASK
A1: TASK #1 | D1: TASK #6 | J1: TASK #10
A2: Row Labels | B2: Sum of REVENUE | D2: Row Labels | E2: Sum of REVENUE | J2: 1. Pizza Hut leads with 265,411.62 in revenue, slightly higher than Burger King and KFC
A3: Pizza Hut | B3: 265411.62 | D3: Burger King | E3: 261988.13 | J3: 2. Multan recorded the highest number of orders among all cities
A4: Grand Total | B4: 265411.62 | D4: KFC | E4: 253854.62 | J4: 3. The majority of customers prefer paying card rather than cash or wallet
D5: McDonald's | E5: 185013.31 | J5: 4. Continental dishes sold the highest quantity among all categories
A6: TASK #2 | D6: Pizza Hut | E6: 265411.62 | J6: 5. The average customer rating is 3.08 out of 5
A7: Row Labels | B7: Count of ORDER ID | D7: Subway | E7: 233308.3
A8: Islamabad | B8: 97 | D8: Grand Total | E8: 1199576
A9: Karachi | B9: 104 | J9: Total Revenue | K9: =SUM('RAW DATA'!$U$2:$U$501) -> 1199576
A10: Lahore | B10: 85 | D10: TASK #7 | J10: Total Orders | K10: 500
A11: Multan | B11: 110 | J11: Average Rating | K11: =AVERAGE(Table1[RATING]) -> 3.0737463
A12: Peshawar | B12: 104 | J12: Quantity Sold | K12: =SUM('RAW DATA'!K2:K501) -> 1480
A13: Grand Total | B13: 500
A15: TASK #3
A16: Row Labels | B16: Count of ORDER ID
A17: Card | B17: 183
A18: Cash | B18: 162
A19: Wallet | B19: 155
A20: Grand Total | B20: 500
A22: TASK #4
A23: Average Rating | B23: =AVERAGE(Table1[RATING]) -> 3.0737463
A27: TASK #5
A28: Row Labels | B28: Sum of QUANTITY
A29: Chinese | B29: 289 | D29: TASK #8
A30: Continental | B30: 334
A31: Dessert | B31: 282
A32: Fast Food | B32: 256
A33: Italian | B33: 319
A34: Grand Total | B34: 1480

Sheet DASHBOARD
C3: DASHBOARD | H3: TOTAL ORDERS | K3: TOTAL REVENUE | M3: AVERAGE RATING | P3: QUANTITY SOLD | R3: TOTAL ORDER FREQUENCY | U3: DATE TODAY:
H4: =H34 -> 500 | K4: =Q34 -> 1199576 | M4: =M34 -> 3.081804 | P4: =K34 -> 1480 | R4: =J34 -> 13044 | U4: =TODAY() -> 46098
D5: HIGHEST REVENUE
C7: Pizza Hut
D11: MOST ORDERS | V11: PAYMENT METHOD
C13: Multan
U14: Card
V17: FOOD CATEGORY
V21: Continental
N25: ORDERS PER MONTH
D26: RESTAURANT NAME | H26: ORDERS | I26: CUSTOMERS | J26: ORDERS FREQUENCY | K26: QUANTITY SOLD | L26: AVERAGE DISH PRICE | M26: RESTAURANT RATING | N26: MAY | O26: JUNE | P26: JULY | Q26: REVENUE | T26: REVENUE SHARE
D27: BURGER KING | H27: =COUNTIF(Table1[RESTAURANT NAME], D27) -> 97 | I27: {=COUNTA(_xlfn.UNIQUE(_xlfn._xlws.FILTER(Table1[CUSTOMER ID], Table1[RESTAURANT NAME] = D27)))} -> 97 | J27: =SUMIF(Table1[RESTAURANT NAME], "Burger King", Table1[ORDER FREQUENCY]) -> 2624 | K27: =SUMIF('RAW DATA'!$H$2:$H$501, D27, 'RAW DATA'!$K$2:$K$501) -> 293 | L27: 894.16 | M27: =AVERAGEIF('RAW DATA'!$H$2:$H$501, "Burger King", 'RAW DATA'!$R$2:$R$501) -> 3.1935484 | N27: {=SUMPRODUCT(('RAW DATA'!$H$2:$H$501="Burger King")*(MONTH('RAW DATA'!$G$2:$G$501)=4))} -> 13 | O27: {=SUMPRODUCT(('RAW DATA'!$H$2:$H$501="Burger King")*(MONTH('RAW DATA'!$G$2:$G$501)=5))} -> 43 | P27: {=SUMPRODUCT(('RAW DATA'!$H$2:$H$501="Burger King")*(MONTH('RAW DATA'!$G$2:$G$501)=6))} -> 41 | Q27: =SUMIF('RAW DATA'!$H$2:$H$501, D27, 'RAW DATA'!$U$2:$U$501) -> 261988.13 | T27: =Q27/$Q$34 -> 0.21840061
D28: KFC | H28: =COUNTIF(Table1[RESTAURANT NAME], D28) -> 99 | I28: {=COUNTA(_xlfn.UNIQUE(_xlfn._xlws.FILTER(Table1[CUSTOMER ID], Table1[RESTAURANT NAME] = D28)))} -> 99 | J28: =SUMIF(Table1[RESTAURANT NAME], "KFC", Table1[ORDER FREQUENCY]) -> 2534 | K28: =SUMIF('RAW DATA'!$H$2:$H$501, D28, 'RAW DATA'!$K$2:$K$501) -> 286 | L28: 887.6 | M28: =AVERAGEIF('RAW DATA'!$H$2:$H$501, "KFC", 'RAW DATA'!$R$2:$R$501) -> 3.0135135 | N28: {=SUMPRODUCT(('RAW DATA'!$H$2:$H$501="KFC")*(MONTH('RAW DATA'!$G$2:$G$501)=4))} -> 13 | O28: {=SUMPRODUCT(('RAW DATA'!$H$2:$H$501="KFC")*(MONTH('RAW DATA'!$G$2:$G$501)=5))} -> 49 | P28: {=SUMPRODUCT(('RAW DATA'!$H$2:$H$501="KFC")*(MONTH('RAW DATA'!$G$2:$G$501)=6))} -> 37 | Q28: =SUMIF('RAW DATA'!$H$2:$H$501, D28, 'RAW DATA'!$U$2:$U$501) -> 253854.62 | T28: =Q28/$Q$34 -> 0.21162029
D29: MCDONALD'S | H29: =COUNTIF(Table1[RESTAURANT NAME], D29) -> 82 | I29: {=COUNTA(_xlfn.UNIQUE(_xlfn._xlws.FILTER(Table1[CUSTOMER ID], Table1[RESTAURANT NAME] = D29)))} -> 82 | J29: =SUMIF(Table1[RESTAURANT NAME], D29, Table1[ORDER FREQUENCY]) -> 1974 | K29: =SUMIF('RAW DATA'!$H$2:$H$501, D29, 'RAW DATA'!$K$2:$K$501) -> 236 | L29: 783.95 | M29: =AVERAGEIF('RAW DATA'!$H$2:$H$501, "McDonald's", 'RAW DATA'!$R$2:$R$501) -> 3.1481481 | N29: {=SUMPRODUCT(('RAW DATA'!$H$2:$H$501="McDonald's")*(MONTH('RAW DATA'!$G$2:$G$501)=4))} -> 11 | O29: {=SUMPRODUCT(('RAW DATA'!$H$2:$H$501="McDonald's")*(MONTH('RAW DATA'!$G$2:$G$501)=5))} -> 40 | P29: {=SUMPRODUCT(('RAW DATA'!$H$2:$H$501="McDonald's")*(MONTH('RAW DATA'!$G$2:$G$501)=6))} -> 31 | Q29: =SUMIF('RAW DATA'!$H$2:$H$501, D29, 'RAW DATA'!$U$2:$U$501) -> 185013.31 | T29: =Q29/$Q$34 -> 0.15423226
D30: PIZZA HUT | H30: =COUNTIF(Table1[RESTAURANT NAME], D30) -> 116 | I30: {=COUNTA(_xlfn.UNIQUE(_xlfn._xlws.FILTER(Table1[CUSTOMER ID], Table1[RESTAURANT NAME] = D30)))} -> 116 | J30: =SUMIF(Table1[RESTAURANT NAME], D30, Table1[ORDER FREQUENCY]) -> 3044 | K30: =SUMIF('RAW DATA'!$H$2:$H$501, D30, 'RAW DATA'!$K$2:$K$501) -> 356 | L30: 745.54 | M30: =AVERAGEIF('RAW DATA'!$H$2:$H$501, D30, 'RAW DATA'!$R$2:$R$501) -> 3.025641 | N30: {=SUMPRODUCT(('RAW DATA'!$H$2:$H$501="Pizza Hut")*(MONTH('RAW DATA'!$G$2:$G$501)=4))} -> 23 | O30: {=SUMPRODUCT(('RAW DATA'!$H$2:$H$501="Pizza Hut")*(MONTH('RAW DATA'!$G$2:$G$501)=5))} -> 56 | P30: {=SUMPRODUCT(('RAW DATA'!$H$2:$H$501="Pizza Hut")*(MONTH('RAW DATA'!$G$2:$G$501)=6))} -> 37 | Q30: =SUMIF('RAW DATA'!$H$2:$H$501, D30, 'RAW DATA'!$U$2:$U$501) -> 265411.62 | T30: =Q30/$Q$34 -> 0.22125453
D31: SUBWAY | H31: =COUNTIF(Table1[RESTAURANT NAME], D31) -> 106 | I31: {=COUNTA(_xlfn.UNIQUE(_xlfn._xlws.FILTER(Table1[CUSTOMER ID], Table1[RESTAURANT NAME] = D31)))} -> 106 | J31: =SUMIF(Table1[RESTAURANT NAME], D31, Table1[ORDER FREQUENCY]) -> 2868 | K31: =SUMIF('RAW DATA'!$H$2:$H$501, D31, 'RAW DATA'!$K$2:$K$501) -> 309 | L31: 755.04 | M31: =AVERAGEIF('RAW DATA'!$H$2:$H$501, D31, 'RAW DATA'!$R$2:$R$501) -> 3.028169 | N31: {=SUMPRODUCT(('RAW DATA'!$H$2:$H$501="Subway")*(MONTH('RAW DATA'!$G$2:$G$501)=4))} -> 13 | O31: {=SUMPRODUCT(('RAW DATA'!$H$2:$H$501="Subway")*(MONTH('RAW DATA'!$G$2:$G$501)=5))} -> 44 | P31: {=SUMPRODUCT(('RAW DATA'!$H$2:$H$501="Subway")*(MONTH('RAW DATA'!$G$2:$G$501)=6))} -> 49 | Q31: =SUMIF('RAW DATA'!$H$2:$H$501, D31, 'RAW DATA'!$U$2:$U$501) -> 233308.3 | T31: =Q31/$Q$34 -> 0.19449231
D33: OVERALL | H33: TOTAL ORDERS | I33: TOTAL CUSTOMER | J33: TOTAL ORDERS FREQUENCY | K33: TOTAL QUANTITY SOLD | L33: AVERAGE DISH PRICE | M33: AVERAGE RATING | N33: MAY ORDERS | O33: JUNE ORDERS | P33: JULY ORDERS | Q33: TOTAL REVENUE
H34: =SUM($H$27:$H$31) -> 500 | I34: =SUM($I$27:$I$31) -> 500 | J34: =SUM($J$27:$J$31) -> 13044 | K34: =SUM(K27:K31) -> 1480 | L34: =AVERAGE(L27:L31) -> 813.258 | M34: =AVERAGE(M27:M31) -> 3.081804 | N34: =SUM(N27:N31) -> 73 | O34: =SUM(O27:O31) -> 232 | P34: =SUM(P27:P31) -> 195 | Q34: =SUM($Q$27:$S$31) -> 1199576
